Traceback (most recent call last):
  File "C:\Users\porod\AppData\Local\Programs\Python\Python310\lib\runpy.py", line 196, in _run_module_as_main
    return _run_code(code, main_globals, None,
  File "C:\Users\porod\AppData\Local\Programs\Python\Python310\lib\runpy.py", line 86, in _run_code
    exec(code, run_globals)
  File "c:\program files\microsoft visual studio\2022\community\common7\ide\extensions\microsoft\python\core\debugpy\__main__.py", line 39, in <module>
    cli.main()
  File "c:\program files\microsoft visual studio\2022\community\common7\ide\extensions\microsoft\python\core\debugpy/..\debugpy\server\cli.py", line 430, in main
    run()
  File "c:\program files\microsoft visual studio\2022\community\common7\ide\extensions\microsoft\python\core\debugpy/..\debugpy\server\cli.py", line 284, in run_file
    runpy.run_path(target, run_name="__main__")
  File "c:\program files\microsoft visual studio\2022\community\common7\ide\extensions\microsoft\python\core\debugpy\_vendored\pydevd\_pydevd_bundle\pydevd_runpy.py", line 320, in run_path
    Поток 0x1 завершился с кодом 0 (0x0).
code, fname = _get_code_from_file(run_name, path_name)
  File "c:\program files\microsoft visual studio\2022\community\common7\ide\extensions\microsoft\python\core\debugpy\_vendored\pydevd\_pydevd_bundle\pydevd_runpy.py", line 294, in _get_code_from_file
    code = compile(f.read(), fname, 'exec')
  File "C:\Users\porod\source\repos\экзамен\экзамен\экзамен.py", line 1
    number = int(input("������� ����������� �����: "))
                                                    ^
SyntaxError: (unicode error) 'utf-8' codec can't decode byte 0xc2 in position 0: invalid continuation byte
Программа "python.exe" завершилась с кодом 1 (0x1).
